<mujoco>
    <worldbody>
        <light diffuse=".5 .5 .5" pos="0 0 2" dir="0 -1 0" />
        <geom type="plane" size="10 10 0.1" rgba="0.5 0.7 1 1" />

        <body name="flappybird" pos="0 0 1" euler="0 0 0">
            <joint type="free" axis="0 0 0" pos="0 0 0" />
            <body name="body" pos="0 0 0" euler="0 0 0">
                <geom type="box" size="0.2760036309724546 0.42138049364763686 0.24275056158535327" rgba="1 1 1 1" mass="0.010656346489080959" />
            </body>

            <body name="wing1" pos=".5 -.3 0" euler="0 -90 0">
                <joint name="joint1" type="hinge" axis="0 1 0" pos="0 0 .25" range="-45 45" />
                <geom type="box" size="0.1 0.1 0.4020299398945306" rgba="1 1 1 1" mass="0.592271212190296" />
            </body>

            <body name="wing2" pos="-.5 -.3 0" euler="0 90 0">
                <joint name="joint2" type="hinge" axis="0 1 0" pos="0 0 .25" range="-45 45" />
                <geom type="box" size="0.1 0.1 0.2182684318914002" rgba="1 1 1 1" mass="0.4918423862194021" />
            </body>
            
        </body>
    </worldbody>

    <actuator>
        <motor joint="joint1" name="m1" gear="10.694140893563553" ctrllimited="true" ctrlrange="-5 5" />
        <motor joint="joint2" name="m2" gear="10.01996553289247" ctrllimited="true" ctrlrange="-5 5" />

</actuator>

</mujoco>