<mujoco>
    <worldbody>
        <light diffuse=".5 .5 .5" pos="0 0 2" dir="0 -1 0" />
        <geom type="plane" size="10 10 0.1" rgba="0.5 0.7 1 1" />

        <body name="flappybird" pos="0 0 1" euler="0 0 0">
            <joint type="free" axis="0 0 0" pos="0 0 0" />
            <body name="body" pos="0 0 0" euler="0 0 0">
                <geom type="box" size="0.2545611512732974 0.4101761992818158 0.307556578966079" rgba="1 1 1 1" mass="0.012385462671495475" />
            </body>

            <body name="wing1" pos=".5 -.3 0" euler="0 -90 0">
                <joint name="joint1" type="hinge" axis="0 1 0" pos="0 0 .25" range="-45 45" />
                <geom type="box" size="0.1 0.10356238926288172 0.4541958790870215" rgba="1 1 1 1" mass="0.4158633061539602" />
            </body>

            <body name="wing2" pos="-.5 -.3 0" euler="0 90 0">
                <joint name="joint2" type="hinge" axis="0 1 0" pos="0 0 .25" range="-45 45" />
                <geom type="box" size="0.10593118406236865 0.1 0.1704167295524012" rgba="1 1 1 1" mass="0.3335500464196756" />
            </body>
            
        </body>
    </worldbody>

    <actuator>
        <motor joint="joint1" name="m1" gear="12.89881665675162" ctrllimited="true" ctrlrange="-5 5" />
        <motor joint="joint2" name="m2" gear="14.325147017742673" ctrllimited="true" ctrlrange="-5 5" />

</actuator>

</mujoco>