<mujoco>
    <worldbody>
        <light diffuse=".5 .5 .5" pos="0 0 2" dir="0 -1 0" />
        <geom type="plane" size="10 10 0.1" rgba="0.5 0.7 1 1" />

        <body name="flappybird" pos="0 0 1" euler="0 0 0">
            <joint type="free" axis="0 0 0" pos="0 0 0" />
            <body name="body" pos="0 0 0" euler="0 0 0">
                <geom type="box" size="0.2696638896679474 0.3967309783493407 0.19408507053786728" rgba="1 1 1 1" mass="0.010701494189025587" />
            </body>

            <body name="wing1" pos=".5 -.3 0" euler="0 -90 0">
                <joint name="joint1" type="hinge" axis="0 1 0" pos="0 0 .25" range="-45 45" />
                <geom type="box" size="0.1 0.1 0.3521913402251084" rgba="1 1 1 1" mass="0.6386475230245537" />
            </body>

            <body name="wing2" pos="-.5 -.3 0" euler="0 90 0">
                <joint name="joint2" type="hinge" axis="0 1 0" pos="0 0 .25" range="-45 45" />
                <geom type="box" size="0.1 0.1 0.26776604336303916" rgba="1 1 1 1" mass="0.542506950033484" />
            </body>
            
        </body>
    </worldbody>

    <actuator>
        <motor joint="joint1" name="m1" gear="11.20998879559358" ctrllimited="true" ctrlrange="-5 5" />
        <motor joint="joint2" name="m2" gear="11.29231314809857" ctrllimited="true" ctrlrange="-5 5" />

</actuator>

</mujoco>