<mujoco>
    <worldbody>
        <light diffuse=".5 .5 .5" pos="0 0 2" dir="0 -1 0" />
        <geom type="plane" size="10 10 0.1" rgba="0.5 0.7 1 1" />

        <body name="flappybird" pos="0 0 1" euler="0 0 0">
            <joint type="free" axis="0 0 0" pos="0 0 0" />
            <body name="body" pos="0 0 0" euler="0 0 0">
                <geom type="box" size="0.3106885537907337 0.3805848973395197 0.28786006838169304" rgba="1 1 1 1" mass="0.01205844612158162" />
            </body>

            <body name="wing1" pos=".5 -.3 0" euler="0 -90 0">
                <joint name="joint1" type="hinge" axis="0 1 0" pos="0 0 .25" range="-45 45" />
                <geom type="box" size="0.12150826126280811 0.1 0.4714683692116851" rgba="1 1 1 1" mass="0.501360265620308" />
            </body>

            <body name="wing2" pos="-.5 -.3 0" euler="0 90 0">
                <joint name="joint2" type="hinge" axis="0 1 0" pos="0 0 .25" range="-45 45" />
                <geom type="box" size="0.13086540848613226 0.1202914620712736 0.1293871467075561" rgba="1 1 1 1" mass="0.27190713745434186" />
            </body>
            
        </body>
    </worldbody>

    <actuator>
        <motor joint="joint1" name="m1" gear="12.539725604582289" ctrllimited="true" ctrlrange="-5 5" />
        <motor joint="joint2" name="m2" gear="16.533542098696124" ctrllimited="true" ctrlrange="-5 5" />

</actuator>

</mujoco>