<mujoco>
    <worldbody>
        <light diffuse=".5 .5 .5" pos="0 0 2" dir="0 -1 0"/>
        <geom type="plane" size="1 1 0.1" rgba=".9 0 0 1"/>
        
        <body pos="0 0 1">
            <joint type="free"/>
            <!-- Body of the car -->
            <geom type="capsule" fromto="0.2 0 0 -0.2 0 0" size="0.1" rgba="0.5 0.5 0.5 1"/>
            <geom type="box" size="0.2 0.1 0.05" rgba="0.5 0.5 0.5 1"/>
            
            <!-- Wheels -->
            <!-- Adjust the size and position to make them look more realistic -->
            <body pos="0.2 0.15 -0.05">
                <joint name="front_left_wheel_joint" type="hinge" axis="0 1 0"/>
                <geom type="cylinder" size="0.05 0.02" rgba="0 0 0 1"/>
            </body>
            <body pos="0.2 -0.15 -0.05">
                <joint name="front_right_wheel_joint" type="hinge" axis="0 1 0"/>
                <geom type="cylinder" size="0.05 0.02" rgba="0 0 0 1"/>
            </body>
            <body pos="-0.2 0.15 -0.05">
                <joint name="rear_left_wheel_joint" type="hinge" axis="0 1 0"/>
                <geom type="cylinder" size="0.05 0.02" rgba="0 0 0 1"/>
            </body>
            <body pos="-0.2 -0.15 -0.05">
                <joint name="rear_right_wheel_joint" type="hinge" axis="0 1 0"/>
                <geom type="cylinder" size="0.05 0.02" rgba="0 0 0 1"/>
            </body>
        </body>
    </worldbody>

    <actuator>
        <motor joint="front_left_wheel_joint" name="motor_front_left" />
        <motor joint="front_right_wheel_joint" name="motor_front_right" />
        <motor joint="rear_left_wheel_joint" name="motor_rear_left" />
        <motor joint="rear_right_wheel_joint" name="motor_rear_right" />
    </actuator>
</mujoco>
