<mujoco>
    <visual>
        <headlight ambient="1 1 1" diffuse="1 1 1" specular="0.1 0.1 0.1"/>
        <map fogstart="3" fogend="5" force="0.1" zfar="10"/>
        <rgba haze="0.6 0.8 0.9 1" fog="0.6 0.8 0.9 1"/>
        <quality shadowsize="2048"/>
    </visual>

    <worldbody>
        <light diffuse="1 1 1" pos="0 0 3" dir="0 -1 0"/> <!-- Bright white light -->
        <geom type="plane" size="5 5 0.1" rgba="0 0 1 .5"/> <!-- Representing surface -->

        <body name="submarine" pos="0 0 1.5">
            <joint type="free"/>
            <!-- No longer a marine life, Gorilla-like creature will be created -->
            <geom type="capsule" fromto="0.2 0 0 -0.2 0 0" size="0.1" rgba="0.1 0.1 0.1 1"/>
            <geom type="box" size="0.2 0.1 0.05" rgba="1 1 1 1"/>
            
            <!-- Limbs -->
            <body pos="0.2 0.15 -0.05">
                <joint name="f_l_limb_joint" type="hinge" axis="0 1 0"/>
                <geom type="capsule" size="0.09 0.05" rgba="0.1 0.1 0.1 0.8"/>
            </body>
            <body pos="0.2 -0.15 -0.05">
                <joint name="f_r_limb_joint" type="hinge" axis="0 1 0"/>
                <geom type="capsule" size="0.09 0.05" rgba="0.1 0.1 0.1 0.8"/>
            </body>
            <body pos="-0.2 0.15 -0.05">
                <joint name="r_l_limb_joint" type="hinge" axis="0 1 0"/>
                <geom type="capsule" size="0.05 0.02" rgba="0.1 0.1 0.1 0.8"/>
            </body>
            <body pos="-0.2 -0.15 -0.05">
                <joint name="r_r_limb_joint" type="hinge" axis="0 1 0"/>
                <geom type="capsule" size="0.05 0.02" rgba="0.1 0.1 0.1 0.8"/>
            </body>
        </body>
    </worldbody>

    <actuator>
        <motor joint="f_l_limb_joint" name="motor_f_l" />
        <motor joint="f_r_limb_joint" name="motor_f_r" />
        <motor joint="r_l_limb_joint" name="motor_r_l" />
        <motor joint="r_r_limb_joint" name="motor_r_r" />
    </actuator>
</mujoco>