<mujoco>
    <worldbody>
        <light diffuse=".5 .5 .5" pos="0 0 2" dir="0 -1 0" />
        <geom type="plane" size="10 10 0.1" rgba="0.5 0.7 1 1" />

        <body name="flappybird" pos="0 0 1" euler="0 0 0">
            <joint type="free" axis="0 0 0" pos="0 0 0" />
            <body name="body" pos="0 0 0" euler="0 0 0">
                <geom type="box" size="0.3082992222031398 0.4294717106645001 0.22486215310825797" rgba="1 1 1 1" mass="0.012076914886598886" />
            </body>

            <body name="wing1" pos=".5 -.3 0" euler="0 -90 0">
                <joint name="joint1" type="hinge" axis="0 1 0" pos="0 0 .25" range="-45 45" />
                <geom type="box" size="0.03983078756905897 0.0572231113141262 0.3517658347585632" rgba="1 1 1 1" mass="0.5442654767902787" />
            </body>

            <body name="wing2" pos="-.5 -.3 0" euler="0 90 0">
                <joint name="joint2" type="hinge" axis="0 1 0" pos="0 0 .25" range="-45 45" />
                <geom type="box" size="0.046463410872432255 0.0456546606006012 0.19343876441741345" rgba="1 1 1 1" mass="0.47834548315168396" />
            </body>
            
        </body>
    </worldbody>

    <actuator>
        <motor joint="joint1" name="m1" gear="8.850206434426687" ctrllimited="true" ctrlrange="-5 5" />
        <motor joint="joint2" name="m2" gear="11.162524863235152" ctrllimited="true" ctrlrange="-5 5" />

</actuator>

</mujoco>