<mujoco>
    <worldbody>
        <light diffuse=".5 .5 .5" pos="0 0 2" dir="0 -1 0" />
        <geom type="plane" size="10 10 0.1" rgba="0.5 0.7 1 1" />

        <body name="flappybird" pos="0 0 1" euler="0 0 0">
            <joint type="free" axis="0 0 0" pos="0 0 0" />
            <body name="body" pos="0 0 0" euler="0 0 0">
                <geom type="box" size="0.27638765788409403 0.4154780133941085 0.16245092992481308" rgba="1 1 1 1" mass="0.01109098027260619" />
            </body>

            <body name="wing1" pos=".5 -.3 0" euler="0 -90 0">
                <joint name="joint1" type="hinge" axis="0 1 0" pos="0 0 .25" range="-45 45" />
                <geom type="box" size="0.02087661206633604 0.07026827987529587 0.414610763834066" rgba="1 1 1 1" mass="0.6634905823604074" />
            </body>

            <body name="wing2" pos="-.5 -.3 0" euler="0 90 0">
                <joint name="joint2" type="hinge" axis="0 1 0" pos="0 0 .25" range="-45 45" />
                <geom type="box" size="0.03083127755810227 0.05707761878007346 0.12535384357019244" rgba="1 1 1 1" mass="0.39429769598387565" />
            </body>
            
        </body>
    </worldbody>

    <actuator>
        <motor joint="joint1" name="m1" gear="11.029274374509697" ctrllimited="true" ctrlrange="-5 5" />
        <motor joint="joint2" name="m2" gear="17.70074482075892" ctrllimited="true" ctrlrange="-5 5" />

</actuator>

</mujoco>