<mujoco>
    <worldbody>
        <light diffuse=".5 .5 .5" pos="0 0 2" dir="0 -1 0" />
        <geom type="plane" size="10 10 0.1" rgba="0.5 0.7 1 1" />

        <body name="flappybird" pos="0 0 1" euler="0 0 0">
            <joint type="free" axis="0 0 0" pos="0 0 0" />
            <body name="body" pos="0 0 0" euler="0 0 0">
                <geom type="box" size="0.2819234218036489 0.42922106796068804 0.19783302235774008" rgba="1 1 1 1" mass="0.009012384866873759" />
            </body>

            <body name="wing1" pos=".5 -.3 0" euler="0 -90 0">
                <joint name="joint1" type="hinge" axis="0 1 0" pos="0 0 .25" range="-45 45" />
                <geom type="box" size="0.02779009974956949 0.07472044885190242 0.3598253618271993" rgba="1 1 1 1" mass="0.6196072842412333" />
            </body>

            <body name="wing2" pos="-.5 -.3 0" euler="0 90 0">
                <joint name="joint2" type="hinge" axis="0 1 0" pos="0 0 .25" range="-45 45" />
                <geom type="box" size="0.03727653073554686 0.04730041549318492 0.13374830338391064" rgba="1 1 1 1" mass="0.5139519655226836" />
            </body>
            
        </body>
    </worldbody>

    <actuator>
        <motor joint="joint1" name="m1" gear="9.770042247774931" ctrllimited="true" ctrlrange="-5 5" />
        <motor joint="joint2" name="m2" gear="15.063708924873312" ctrllimited="true" ctrlrange="-5 5" />

</actuator>

</mujoco>